Workbook

Sheet Instructions for Use
A1: Instructions for using Cq output template
A2: 1. Analyse QuantstudioTM 5 runfile using Design and Analysis v2.6.0 as per package insert instructions.
A3: 2. To export data click the Actions button in the right hand corner of DA2 software. Select Export to save file in location of choice in a .xlsx format.
A4: 3. Open the results .xlsx generated. | Q4: Figure 1. Region of data to select to paste into data input tab
A5: 4. Select all data points from the first well - excluding the headers, as seen in Figure 1. Copy into the second tab of this workbook labelled Data input. | P5: #VALUE!
A6: 5. In the Results Summary tab are the cqs for each channel as well as the VITA indices for NG and CT which are used to assess viability.
A8: NOTE: The analysis in this sheet is automated and changing any of the cells in the sheets other than 'Data Input' may break formulae.
A9: Please contact insignia@speedx.com.au for assistance.

Sheet Data Input
A1: Reporters | B1: Enter all Reporters
A2: FAM
A3: VIC
A4: ATTO101
A5: CY5
A6: CY5.5
A9: Well | B9: Well Position | C9: Omit | D9: Sample | E9: Target | F9: Task | G9: Reporter | H9: Quencher | I9: Amp Status | J9: Amp Score | K9: Curve Quality | L9: Result Quality Issues | M9: Cq | N9: Cq Confidence | O9: Cq Mean | P9: Cq SD | Q9: Auto Threshold | R9: Threshold | S9: Auto Baseline | T9: Baseline Start | U9: Baseline End
A10: 1 | B10: A1 | C10: FALSE | D10: OM3-001_0 min | E10: NG GAT | F10: UNKNOWN | G10: VIC | H10: None | I10: Amp | J10: 2.7615652 | M10: 29.146242 | N10: 0.94831963 | O10: 29.146242 | Q10: FALSE | R10: 74142.9 | S10: TRUE | T10: 3 | U10: 19
A11: 1 | B11: A1 | C11: FALSE | D11: OM3-001_0 min | E11: NG NED | F11: UNKNOWN | G11: CY5 | H11: None | I11: Amp | J11: 2.6560833 | M11: 32.168683 | N11: 0.90271863 | O11: 32.168683 | Q11: FALSE | R11: 46910.863 | S11: TRUE | T11: 3 | U11: 24
A12: 1 | B12: A1 | C12: FALSE | D12: OM3-001_0 min | E12: CT NED | F12: UNKNOWN | G12: ATTO101 | H12: None | I12: No Amp | J12: 0 | M12: Undetermined | N12: 0 | Q12: FALSE | R12: 69932.437 | S12: TRUE | T12: 3 | U12: 49
A13: 1 | B13: A1 | C13: FALSE | D13: OM3-001_0 min | E13: EC | F13: UNKNOWN | G13: CY5.5 | H13: None | I13: Amp | J13: 2.5599366 | M13: 25.555588 | N13: 0.8950969 | O13: 25.555588 | Q13: FALSE | R13: 47660.913 | S13: TRUE | T13: 3 | U13: 17
A14: 1 | B14: A1 | C14: FALSE | D14: OM3-001_0 min | E14: CT GAT | F14: UNKNOWN | G14: FAM | H14: None | I14: Inconclusive | J14: 0 | M14: Undetermined | N14: 0 | Q14: FALSE | R14: 161088.07 | S14: TRUE | T14: 3 | U14: 49
A15: 2 | B15: A2 | C15: FALSE | D15: OM3-001_5 min | E15: NG GAT | F15: UNKNOWN | G15: VIC | H15: None | I15: Amp | J15: 2.7429426 | M15: 29.199535 | N15: 0.97956713 | O15: 29.199535 | Q15: FALSE | R15: 74142.9 | S15: TRUE | T15: 3 | U15: 21
A16: 2 | B16: A2 | C16: FALSE | D16: OM3-001_5 min | E16: NG NED | F16: UNKNOWN | G16: CY5 | H16: None | I16: Amp | J16: 2.6533128 | M16: 32.394623 | N16: 0.93205005 | O16: 32.394623 | Q16: FALSE | R16: 46910.863 | S16: TRUE | T16: 3 | U16: 25
A17: 2 | B17: A2 | C17: FALSE | D17: OM3-001_5 min | E17: CT NED | F17: UNKNOWN | G17: ATTO101 | H17: None | I17: No Amp | J17: 0 | M17: Undetermined | N17: 0 | Q17: FALSE | R17: 69932.437 | S17: TRUE | T17: 3 | U17: 49
A18: 2 | B18: A2 | C18: FALSE | D18: OM3-001_5 min | E18: EC | F18: UNKNOWN | G18: CY5.5 | H18: None | I18: Amp | J18: 2.5671184 | M18: 26.303907 | N18: 0.92983661 | O18: 26.303907 | Q18: FALSE | R18: 47660.913 | S18: TRUE | T18: 3 | U18: 17
A19: 2 | B19: A2 | C19: FALSE | D19: OM3-001_5 min | E19: CT GAT | F19: UNKNOWN | G19: FAM | H19: None | I19: No Amp | J19: 2.1315131 | M19: Undetermined | N19: 0 | Q19: FALSE | R19: 161088.07 | S19: TRUE | T19: 3 | U19: 49
A20: 3 | B20: A3 | C20: FALSE | D20: OM3-001_30 min | E20: NG GAT | F20: UNKNOWN | G20: VIC | H20: None | I20: Amp | J20: 2.7554183 | M20: 30.558692 | N20: 0.95666818 | O20: 30.558692 | Q20: FALSE | R20: 74142.9 | S20: TRUE | T20: 3 | U20: 20
A21: 3 | B21: A3 | C21: FALSE | D21: OM3-001_30 min | E21: NG NED | F21: UNKNOWN | G21: CY5 | H21: None | I21: Amp | J21: 2.690759 | M21: 33.338086 | N21: 0.89359767 | O21: 33.338086 | Q21: FALSE | R21: 46910.863 | S21: TRUE | T21: 3 | U21: 25
A22: 3 | B22: A3 | C22: FALSE | D22: OM3-001_30 min | E22: CT NED | F22: UNKNOWN | G22: ATTO101 | H22: None | I22: No Amp | J22: 0 | M22: Undetermined | N22: 0 | Q22: FALSE | R22: 69932.437 | S22: TRUE | T22: 3 | U22: 49
A23: 3 | B23: A3 | C23: FALSE | D23: OM3-001_30 min | E23: EC | F23: UNKNOWN | G23: CY5.5 | H23: None | I23: Amp | J23: 2.6132451 | M23: 28.071379 | N23: 0.9504129 | O23: 28.071379 | Q23: FALSE | R23: 47660.913 | S23: TRUE | T23: 3 | U23: 20
A24: 3 | B24: A3 | C24: FALSE | D24: OM3-001_30 min | E24: CT GAT | F24: UNKNOWN | G24: FAM | H24: None | I24: No Amp | J24: 0 | M24: Undetermined | N24: 0 | Q24: FALSE | R24: 161088.07 | S24: TRUE | T24: 3 | U24: 49
A25: 4 | B25: A4 | C25: FALSE | D25: OM3-001_60 min | E25: NG GAT | F25: UNKNOWN | G25: VIC | H25: None | I25: Amp | J25: 2.7452249 | M25: 31.510965 | N25: 0.96804567 | O25: 31.510965 | Q25: FALSE | R25: 74142.9 | S25: TRUE | T25: 3 | U25: 22
A26: 4 | B26: A4 | C26: FALSE | D26: OM3-001_60 min | E26: NG NED | F26: UNKNOWN | G26: CY5 | H26: None | I26: Amp | J26: 2.5916022 | M26: 34.716424 | N26: 0.88279332 | O26: 34.716424 | Q26: FALSE | R26: 46910.863 | S26: TRUE | T26: 3 | U26: 25
A27: 4 | B27: A4 | C27: FALSE | D27: OM3-001_60 min | E27: CT NED | F27: UNKNOWN | G27: ATTO101 | H27: None | I27: No Amp | J27: 1.8979552 | M27: Undetermined | N27: 0 | Q27: FALSE | R27: 69932.437 | S27: TRUE | T27: 3 | U27: 49
A28: 4 | B28: A4 | C28: FALSE | D28: OM3-001_60 min | E28: EC | F28: UNKNOWN | G28: CY5.5 | H28: None | I28: Amp | J28: 2.6242765 | M28: 26.329329 | N28: 0.93585569 | O28: 26.329329 | Q28: FALSE | R28: 47660.913 | S28: TRUE | T28: 3 | U28: 17
A29: 4 | B29: A4 | C29: FALSE | D29: OM3-001_60 min | E29: CT GAT | F29: UNKNOWN | G29: FAM | H29: None | I29: Inconclusive | J29: 0 | M29: Undetermined | N29: 0 | Q29: FALSE | R29: 161088.07 | S29: TRUE | T29: 3 | U29: 49
A30: 5 | B30: A5 | C30: FALSE | D30: OM3-001_120 min | E30: NG GAT | F30: UNKNOWN | G30: VIC | H30: None | I30: Amp | J30: 2.7787915 | M30: 28.133257 | N30: 0.95545381 | O30: 28.133257 | Q30: FALSE | R30: 74142.9 | S30: TRUE | T30: 3 | U30: 19
A31: 5 | B31: A5 | C31: FALSE | D31: OM3-001_120 min | E31: NG NED | F31: UNKNOWN | G31: CY5 | H31: None | I31: Amp | J31: 2.7241364 | M31: 31.208038 | N31: 0.93521969 | O31: 31.208038 | Q31: FALSE | R31: 46910.863 | S31: TRUE | T31: 3 | U31: 25
A32: 5 | B32: A5 | C32: FALSE | D32: OM3-001_120 min | E32: CT NED | F32: UNKNOWN | G32: ATTO101 | H32: None | I32: Inconclusive | J32: 0 | M32: Undetermined | N32: 0 | Q32: FALSE | R32: 69932.437 | S32: TRUE | T32: 3 | U32: 49
A33: 5 | B33: A5 | C33: FALSE | D33: OM3-001_120 min | E33: EC | F33: UNKNOWN | G33: CY5.5 | H33: None | I33: Amp | J33: 2.655161 | M33: 27.051462 | N33: 0.91877235 | O33: 27.051462 | Q33: FALSE | R33: 47660.913 | S33: TRUE | T33: 3 | U33: 19
A34: 5 | B34: A5 | C34: FALSE | D34: OM3-001_120 min | E34: CT GAT | F34: UNKNOWN | G34: FAM | H34: None | I34: Inconclusive | J34: 0 | M34: Undetermined | N34: 0 | Q34: FALSE | R34: 161088.07 | S34: TRUE | T34: 3 | U34: 49
A35: 6 | B35: A6 | C35: FALSE | D35: OM3-009_0 min | E35: NG GAT | F35: UNKNOWN | G35: VIC | H35: None | I35: Amp | J35: 2.3281551 | M35: 38.616128 | N35: 0.65959008 | O35: 38.616128 | Q35: FALSE | R35: 74142.9 | S35: TRUE | T35: 3 | U35: 23
A36: 6 | B36: A6 | C36: FALSE | D36: OM3-009_0 min | E36: NG NED | F36: UNKNOWN | G36: CY5 | H36: None | I36: Amp | J36: 2.349127 | M36: 36.908336 | N36: 0.67747465 | O36: 36.908336 | Q36: FALSE | R36: 46910.863 | S36: TRUE | T36: 3 | U36: 28
A37: 6 | B37: A6 | C37: FALSE | D37: OM3-009_0 min | E37: CT NED | F37: UNKNOWN | G37: ATTO101 | H37: None | I37: Inconclusive | J37: 0 | M37: Undetermined | N37: 0 | Q37: FALSE | R37: 69932.437 | S37: TRUE | T37: 3 | U37: 49
A38: 6 | B38: A6 | C38: FALSE | D38: OM3-009_0 min | E38: EC | F38: UNKNOWN | G38: CY5.5 | H38: None | I38: Amp | J38: 2.6486269 | M38: 23.08984 | N38: 0.95373459 | O38: 23.08984 | Q38: FALSE | R38: 47660.913 | S38: TRUE | T38: 3 | U38: 13
A39: 6 | B39: A6 | C39: FALSE | D39: OM3-009_0 min | E39: CT GAT | F39: UNKNOWN | G39: FAM | H39: None | I39: No Amp | J39: 0 | M39: Undetermined | N39: 0 | Q39: FALSE | R39: 161088.07 | S39: TRUE | T39: 3 | U39: 49
A40: 7 | B40: A7 | C40: FALSE | D40: OM3-009_5 min | E40: NG GAT | F40: UNKNOWN | G40: VIC | H40: None | I40: Amp | J40: 2.3740157 | M40: 38.389233 | N40: 0.80027979 | O40: 38.389233 | Q40: FALSE | R40: 74142.9 | S40: TRUE | T40: 3 | U40: 24
A41: 7 | B41: A7 | C41: FALSE | D41: OM3-009_5 min | E41: NG NED | F41: UNKNOWN | G41: CY5 | H41: None | I41: Amp | J41: 2.2910637 | M41: 40.160181 | N41: 0.63216151 | O41: 40.160181 | Q41: FALSE | R41: 46910.863 | S41: TRUE | T41: 3 | U41: 32
A42: 7 | B42: A7 | C42: FALSE | D42: OM3-009_5 min | E42: CT NED | F42: UNKNOWN | G42: ATTO101 | H42: None | I42: Inconclusive | J42: 0 | M42: Undetermined | N42: 0 | Q42: FALSE | R42: 69932.437 | S42: TRUE | T42: 3 | U42: 49
...

Sheet Cq and Delta Cq
A1: Well Position | B1: Sample | C1: FAM | D1: ATTO101 | E1: CY5.5 | F1: VIC | G1: CY5 | I1: CT ΔCq (NED-GAT) | J1: NG ΔCq (NED-GAT)
A2: ='Data Input'!B14 -> A1 | B2: ='Data Input'!D14 -> OM3-001_0 min | C2: {=_xlfn.XLOOKUP(1,(Tbl_Input[Well Position]='Cq and Delta Cq'!$A$2)*(Tbl_Input[Reporter]='Cq and Delta Cq'!$C$1),Tbl_Input[Cq])} -> Undetermined | D2: {=_xlfn.XLOOKUP(1,(Tbl_Input[Well Position]='Cq and Delta Cq'!$A$2)*(Tbl_Input[Reporter]='Cq and Delta Cq'!$D$1),Tbl_Input[Cq])} -> Undetermined | E2: {=_xlfn.XLOOKUP(1,(Tbl_Input[Well Position]='Cq and Delta Cq'!$A$2)*(Tbl_Input[Reporter]='Cq and Delta Cq'!$E$1),Tbl_Input[Cq])} -> 25.555588 | F2: {=_xlfn.XLOOKUP(1,(Tbl_Input[Well Position]='Cq and Delta Cq'!$A$2)*(Tbl_Input[Reporter]='Cq and Delta Cq'!$F$1),Tbl_Input[Cq])} -> 29.146242 | G2: {=_xlfn.XLOOKUP(1,(Tbl_Input[Well Position]='Cq and Delta Cq'!$A$2)*(Tbl_Input[Reporter]='Cq and Delta Cq'!$G$1),Tbl_Input[Cq])} -> 32.168683 | I2: =D2-C2 -> #VALUE! | J2: =G2-F2 -> 3.0224409
A3: ='Data Input'!B19 -> A2 | B3: ='Data Input'!D19 -> OM3-001_5 min | C3: {=_xlfn.XLOOKUP(1,(Tbl_Input[Well Position]='Cq and Delta Cq'!A3)*(Tbl_Input[Reporter]='Cq and Delta Cq'!$C$1),Tbl_Input[Cq])} -> Undetermined | D3: {=_xlfn.XLOOKUP(1,(Tbl_Input[Well Position]='Cq and Delta Cq'!A3)*(Tbl_Input[Reporter]='Cq and Delta Cq'!$D$1),Tbl_Input[Cq])} -> Undetermined | E3: {=_xlfn.XLOOKUP(1,(Tbl_Input[Well Position]='Cq and Delta Cq'!A3)*(Tbl_Input[Reporter]='Cq and Delta Cq'!$E$1),Tbl_Input[Cq])} -> 26.303907 | F3: {=_xlfn.XLOOKUP(1,(Tbl_Input[Well Position]='Cq and Delta Cq'!A3)*(Tbl_Input[Reporter]='Cq and Delta Cq'!$F$1),Tbl_Input[Cq])} -> 29.199535 | G3: {=_xlfn.XLOOKUP(1,(Tbl_Input[Well Position]='Cq and Delta Cq'!A3)*(Tbl_Input[Reporter]='Cq and Delta Cq'!$G$1),Tbl_Input[Cq])} -> 32.394623 | I3: =D3-C3 -> #VALUE! | J3: =G3-F3 -> 3.1950878
A4: ='Data Input'!B24 -> A3 | B4: ='Data Input'!D24 -> OM3-001_30 min | C4: {=_xlfn.XLOOKUP(1,(Tbl_Input[Well Position]='Cq and Delta Cq'!A4)*(Tbl_Input[Reporter]='Cq and Delta Cq'!$C$1),Tbl_Input[Cq])} -> Undetermined | D4: {=_xlfn.XLOOKUP(1,(Tbl_Input[Well Position]='Cq and Delta Cq'!A4)*(Tbl_Input[Reporter]='Cq and Delta Cq'!$D$1),Tbl_Input[Cq])} -> Undetermined | E4: {=_xlfn.XLOOKUP(1,(Tbl_Input[Well Position]='Cq and Delta Cq'!A4)*(Tbl_Input[Reporter]='Cq and Delta Cq'!$E$1),Tbl_Input[Cq])} -> 28.071379 | F4: {=_xlfn.XLOOKUP(1,(Tbl_Input[Well Position]='Cq and Delta Cq'!A4)*(Tbl_Input[Reporter]='Cq and Delta Cq'!$F$1),Tbl_Input[Cq])} -> 30.558692 | G4: {=_xlfn.XLOOKUP(1,(Tbl_Input[Well Position]='Cq and Delta Cq'!A4)*(Tbl_Input[Reporter]='Cq and Delta Cq'!$G$1),Tbl_Input[Cq])} -> 33.338086 | I4: =D4-C4 -> #VALUE! | J4: =G4-F4 -> 2.7793946
A5: ='Data Input'!B29 -> A4 | B5: ='Data Input'!D29 -> OM3-001_60 min | C5: {=_xlfn.XLOOKUP(1,(Tbl_Input[Well Position]='Cq and Delta Cq'!A5)*(Tbl_Input[Reporter]='Cq and Delta Cq'!$C$1),Tbl_Input[Cq])} -> Undetermined | D5: {=_xlfn.XLOOKUP(1,(Tbl_Input[Well Position]='Cq and Delta Cq'!A5)*(Tbl_Input[Reporter]='Cq and Delta Cq'!$D$1),Tbl_Input[Cq])} -> Undetermined | E5: {=_xlfn.XLOOKUP(1,(Tbl_Input[Well Position]='Cq and Delta Cq'!A5)*(Tbl_Input[Reporter]='Cq and Delta Cq'!$E$1),Tbl_Input[Cq])} -> 26.329329 | F5: {=_xlfn.XLOOKUP(1,(Tbl_Input[Well Position]='Cq and Delta Cq'!A5)*(Tbl_Input[Reporter]='Cq and Delta Cq'!$F$1),Tbl_Input[Cq])} -> 31.510965 | G5: {=_xlfn.XLOOKUP(1,(Tbl_Input[Well Position]='Cq and Delta Cq'!A5)*(Tbl_Input[Reporter]='Cq and Delta Cq'!$G$1),Tbl_Input[Cq])} -> 34.716424 | I5: =D5-C5 -> #VALUE! | J5: =G5-F5 -> 3.205459
A6: ='Data Input'!B34 -> A5 | B6: ='Data Input'!D34 -> OM3-001_120 min | C6: {=_xlfn.XLOOKUP(1,(Tbl_Input[Well Position]='Cq and Delta Cq'!A6)*(Tbl_Input[Reporter]='Cq and Delta Cq'!$C$1),Tbl_Input[Cq])} -> Undetermined | D6: {=_xlfn.XLOOKUP(1,(Tbl_Input[Well Position]='Cq and Delta Cq'!A6)*(Tbl_Input[Reporter]='Cq and Delta Cq'!$D$1),Tbl_Input[Cq])} -> Undetermined | E6: {=_xlfn.XLOOKUP(1,(Tbl_Input[Well Position]='Cq and Delta Cq'!A6)*(Tbl_Input[Reporter]='Cq and Delta Cq'!$E$1),Tbl_Input[Cq])} -> 27.051462 | F6: {=_xlfn.XLOOKUP(1,(Tbl_Input[Well Position]='Cq and Delta Cq'!A6)*(Tbl_Input[Reporter]='Cq and Delta Cq'!$F$1),Tbl_Input[Cq])} -> 28.133257 | G6: {=_xlfn.XLOOKUP(1,(Tbl_Input[Well Position]='Cq and Delta Cq'!A6)*(Tbl_Input[Reporter]='Cq and Delta Cq'!$G$1),Tbl_Input[Cq])} -> 31.208038 | I6: =D6-C6 -> #VALUE! | J6: =G6-F6 -> 3.0747814
A7: ='Data Input'!B39 -> A6 | B7: ='Data Input'!D39 -> OM3-009_0 min | C7: {=_xlfn.XLOOKUP(1,(Tbl_Input[Well Position]='Cq and Delta Cq'!A7)*(Tbl_Input[Reporter]='Cq and Delta Cq'!$C$1),Tbl_Input[Cq])} -> Undetermined | D7: {=_xlfn.XLOOKUP(1,(Tbl_Input[Well Position]='Cq and Delta Cq'!A7)*(Tbl_Input[Reporter]='Cq and Delta Cq'!$D$1),Tbl_Input[Cq])} -> Undetermined | E7: {=_xlfn.XLOOKUP(1,(Tbl_Input[Well Position]='Cq and Delta Cq'!A7)*(Tbl_Input[Reporter]='Cq and Delta Cq'!$E$1),Tbl_Input[Cq])} -> 23.08984 | F7: {=_xlfn.XLOOKUP(1,(Tbl_Input[Well Position]='Cq and Delta Cq'!A7)*(Tbl_Input[Reporter]='Cq and Delta Cq'!$F$1),Tbl_Input[Cq])} -> 38.616128 | G7: {=_xlfn.XLOOKUP(1,(Tbl_Input[Well Position]='Cq and Delta Cq'!A7)*(Tbl_Input[Reporter]='Cq and Delta Cq'!$G$1),Tbl_Input[Cq])} -> 36.908336 | I7: =D7-C7 -> #VALUE! | J7: =G7-F7 -> -1.7077929
A8: ='Data Input'!B44 -> A7 | B8: ='Data Input'!D44 -> OM3-009_5 min | C8: {=_xlfn.XLOOKUP(1,(Tbl_Input[Well Position]='Cq and Delta Cq'!A8)*(Tbl_Input[Reporter]='Cq and Delta Cq'!$C$1),Tbl_Input[Cq])} -> Undetermined | D8: {=_xlfn.XLOOKUP(1,(Tbl_Input[Well Position]='Cq and Delta Cq'!A8)*(Tbl_Input[Reporter]='Cq and Delta Cq'!$D$1),Tbl_Input[Cq])} -> Undetermined | E8: {=_xlfn.XLOOKUP(1,(Tbl_Input[Well Position]='Cq and Delta Cq'!A8)*(Tbl_Input[Reporter]='Cq and Delta Cq'!$E$1),Tbl_Input[Cq])} -> 25.275917 | F8: {=_xlfn.XLOOKUP(1,(Tbl_Input[Well Position]='Cq and Delta Cq'!A8)*(Tbl_Input[Reporter]='Cq and Delta Cq'!$F$1),Tbl_Input[Cq])} -> 38.389233 | G8: {=_xlfn.XLOOKUP(1,(Tbl_Input[Well Position]='Cq and Delta Cq'!A8)*(Tbl_Input[Reporter]='Cq and Delta Cq'!$G$1),Tbl_Input[Cq])} -> 40.160181 | I8: =D8-C8 -> #VALUE! | J8: =G8-F8 -> 1.7709484
A9: ='Data Input'!B49 -> A8 | B9: ='Data Input'!D49 -> OM3-009_30 min | C9: {=_xlfn.XLOOKUP(1,(Tbl_Input[Well Position]='Cq and Delta Cq'!A9)*(Tbl_Input[Reporter]='Cq and Delta Cq'!$C$1),Tbl_Input[Cq])} -> Undetermined | D9: {=_xlfn.XLOOKUP(1,(Tbl_Input[Well Position]='Cq and Delta Cq'!A9)*(Tbl_Input[Reporter]='Cq and Delta Cq'!$D$1),Tbl_Input[Cq])} -> Undetermined | E9: {=_xlfn.XLOOKUP(1,(Tbl_Input[Well Position]='Cq and Delta Cq'!A9)*(Tbl_Input[Reporter]='Cq and Delta Cq'!$E$1),Tbl_Input[Cq])} -> 25.029158 | F9: {=_xlfn.XLOOKUP(1,(Tbl_Input[Well Position]='Cq and Delta Cq'!A9)*(Tbl_Input[Reporter]='Cq and Delta Cq'!$F$1),Tbl_Input[Cq])} -> 32.119947 | G9: {=_xlfn.XLOOKUP(1,(Tbl_Input[Well Position]='Cq and Delta Cq'!A9)*(Tbl_Input[Reporter]='Cq and Delta Cq'!$G$1),Tbl_Input[Cq])} -> 33.282399 | I9: =D9-C9 -> #VALUE! | J9: =G9-F9 -> 1.1624525
A10: ='Data Input'!B54 -> A9 | B10: ='Data Input'!D54 -> OM3-009_60 min | C10: {=_xlfn.XLOOKUP(1,(Tbl_Input[Well Position]='Cq and Delta Cq'!A10)*(Tbl_Input[Reporter]='Cq and Delta Cq'!$C$1),Tbl_Input[Cq])} -> Undetermined | D10: {=_xlfn.XLOOKUP(1,(Tbl_Input[Well Position]='Cq and Delta Cq'!A10)*(Tbl_Input[Reporter]='Cq and Delta Cq'!$D$1),Tbl_Input[Cq])} -> Undetermined | E10: {=_xlfn.XLOOKUP(1,(Tbl_Input[Well Position]='Cq and Delta Cq'!A10)*(Tbl_Input[Reporter]='Cq and Delta Cq'!$E$1),Tbl_Input[Cq])} -> 24.559491 | F10: {=_xlfn.XLOOKUP(1,(Tbl_Input[Well Position]='Cq and Delta Cq'!A10)*(Tbl_Input[Reporter]='Cq and Delta Cq'!$F$1),Tbl_Input[Cq])} -> 37.311378 | G10: {=_xlfn.XLOOKUP(1,(Tbl_Input[Well Position]='Cq and Delta Cq'!A10)*(Tbl_Input[Reporter]='Cq and Delta Cq'!$G$1),Tbl_Input[Cq])} -> 35.827766 | I10: =D10-C10 -> #VALUE! | J10: =G10-F10 -> -1.483612
A11: ='Data Input'!B59 -> A10 | B11: ='Data Input'!D59 -> OM3-009_120 min | C11: {=_xlfn.XLOOKUP(1,(Tbl_Input[Well Position]='Cq and Delta Cq'!A11)*(Tbl_Input[Reporter]='Cq and Delta Cq'!$C$1),Tbl_Input[Cq])} -> Undetermined | D11: {=_xlfn.XLOOKUP(1,(Tbl_Input[Well Position]='Cq and Delta Cq'!A11)*(Tbl_Input[Reporter]='Cq and Delta Cq'!$D$1),Tbl_Input[Cq])} -> Undetermined | E11: {=_xlfn.XLOOKUP(1,(Tbl_Input[Well Position]='Cq and Delta Cq'!A11)*(Tbl_Input[Reporter]='Cq and Delta Cq'!$E$1),Tbl_Input[Cq])} -> 24.508035 | F11: {=_xlfn.XLOOKUP(1,(Tbl_Input[Well Position]='Cq and Delta Cq'!A11)*(Tbl_Input[Reporter]='Cq and Delta Cq'!$F$1),Tbl_Input[Cq])} -> 29.241216 | G11: {=_xlfn.XLOOKUP(1,(Tbl_Input[Well Position]='Cq and Delta Cq'!A11)*(Tbl_Input[Reporter]='Cq and Delta Cq'!$G$1),Tbl_Input[Cq])} -> 30.974218 | I11: =D11-C11 -> #VALUE! | J11: =G11-F11 -> 1.7330027
A12: ='Data Input'!B64 -> A12 | B12: ='Data Input'!D64 -> NEG | C12: {=_xlfn.XLOOKUP(1,(Tbl_Input[Well Position]='Cq and Delta Cq'!A12)*(Tbl_Input[Reporter]='Cq and Delta Cq'!$C$1),Tbl_Input[Cq])} -> Undetermined | D12: {=_xlfn.XLOOKUP(1,(Tbl_Input[Well Position]='Cq and Delta Cq'!A12)*(Tbl_Input[Reporter]='Cq and Delta Cq'!$D$1),Tbl_Input[Cq])} -> Undetermined | E12: {=_xlfn.XLOOKUP(1,(Tbl_Input[Well Position]='Cq and Delta Cq'!A12)*(Tbl_Input[Reporter]='Cq and Delta Cq'!$E$1),Tbl_Input[Cq])} -> Undetermined | F12: {=_xlfn.XLOOKUP(1,(Tbl_Input[Well Position]='Cq and Delta Cq'!A12)*(Tbl_Input[Reporter]='Cq and Delta Cq'!$F$1),Tbl_Input[Cq])} -> Undetermined | G12: {=_xlfn.XLOOKUP(1,(Tbl_Input[Well Position]='Cq and Delta Cq'!A12)*(Tbl_Input[Reporter]='Cq and Delta Cq'!$G$1),Tbl_Input[Cq])} -> Undetermined | I12: =D12-C12 -> #VALUE! | J12: =G12-F12 -> #VALUE!
A13: ='Data Input'!B69 -> B1 | B13: ='Data Input'!D69 -> OM3-002_0 min | C13: {=_xlfn.XLOOKUP(1,(Tbl_Input[Well Position]='Cq and Delta Cq'!A13)*(Tbl_Input[Reporter]='Cq and Delta Cq'!$C$1),Tbl_Input[Cq])} -> Undetermined | D13: {=_xlfn.XLOOKUP(1,(Tbl_Input[Well Position]='Cq and Delta Cq'!A13)*(Tbl_Input[Reporter]='Cq and Delta Cq'!$D$1),Tbl_Input[Cq])} -> Undetermined | E13: {=_xlfn.XLOOKUP(1,(Tbl_Input[Well Position]='Cq and Delta Cq'!A13)*(Tbl_Input[Reporter]='Cq and Delta Cq'!$E$1),Tbl_Input[Cq])} -> 23.940914 | F13: {=_xlfn.XLOOKUP(1,(Tbl_Input[Well Position]='Cq and Delta Cq'!A13)*(Tbl_Input[Reporter]='Cq and Delta Cq'!$F$1),Tbl_Input[Cq])} -> 28.73213 | G13: {=_xlfn.XLOOKUP(1,(Tbl_Input[Well Position]='Cq and Delta Cq'!A13)*(Tbl_Input[Reporter]='Cq and Delta Cq'!$G$1),Tbl_Input[Cq])} -> 29.94156 | I13: =D13-C13 -> #VALUE! | J13: =G13-F13 -> 1.20943
A14: ='Data Input'!B74 -> B2 | B14: ='Data Input'!D74 -> OM3-002_5 min | C14: {=_xlfn.XLOOKUP(1,(Tbl_Input[Well Position]='Cq and Delta Cq'!A14)*(Tbl_Input[Reporter]='Cq and Delta Cq'!$C$1),Tbl_Input[Cq])} -> Undetermined | D14: {=_xlfn.XLOOKUP(1,(Tbl_Input[Well Position]='Cq and Delta Cq'!A14)*(Tbl_Input[Reporter]='Cq and Delta Cq'!$D$1),Tbl_Input[Cq])} -> Undetermined | E14: {=_xlfn.XLOOKUP(1,(Tbl_Input[Well Position]='Cq and Delta Cq'!A14)*(Tbl_Input[Reporter]='Cq and Delta Cq'!$E$1),Tbl_Input[Cq])} -> 25.702258 | F14: {=_xlfn.XLOOKUP(1,(Tbl_Input[Well Position]='Cq and Delta Cq'!A14)*(Tbl_Input[Reporter]='Cq and Delta Cq'!$F$1),Tbl_Input[Cq])} -> 28.241612 | G14: {=_xlfn.XLOOKUP(1,(Tbl_Input[Well Position]='Cq and Delta Cq'!A14)*(Tbl_Input[Reporter]='Cq and Delta Cq'!$G$1),Tbl_Input[Cq])} -> 30.298672 | I14: =D14-C14 -> #VALUE! | J14: =G14-F14 -> 2.0570604
A15: ='Data Input'!B79 -> B3 | B15: ='Data Input'!D79 -> OM3-002_30 min | C15: {=_xlfn.XLOOKUP(1,(Tbl_Input[Well Position]='Cq and Delta Cq'!A15)*(Tbl_Input[Reporter]='Cq and Delta Cq'!$C$1),Tbl_Input[Cq])} -> Undetermined | D15: {=_xlfn.XLOOKUP(1,(Tbl_Input[Well Position]='Cq and Delta Cq'!A15)*(Tbl_Input[Reporter]='Cq and Delta Cq'!$D$1),Tbl_Input[Cq])} -> Undetermined | E15: {=_xlfn.XLOOKUP(1,(Tbl_Input[Well Position]='Cq and Delta Cq'!A15)*(Tbl_Input[Reporter]='Cq and Delta Cq'!$E$1),Tbl_Input[Cq])} -> 24.459486 | F15: {=_xlfn.XLOOKUP(1,(Tbl_Input[Well Position]='Cq and Delta Cq'!A15)*(Tbl_Input[Reporter]='Cq and Delta Cq'!$F$1),Tbl_Input[Cq])} -> 28.000809 | G15: {=_xlfn.XLOOKUP(1,(Tbl_Input[Well Position]='Cq and Delta Cq'!A15)*(Tbl_Input[Reporter]='Cq and Delta Cq'!$G$1),Tbl_Input[Cq])} -> 30.577444 | I15: =D15-C15 -> #VALUE! | J15: =G15-F15 -> 2.5766352
A16: ='Data Input'!B84 -> B4 | B16: ='Data Input'!D84 -> OM3-002_60 min | C16: {=_xlfn.XLOOKUP(1,(Tbl_Input[Well Position]='Cq and Delta Cq'!A16)*(Tbl_Input[Reporter]='Cq and Delta Cq'!$C$1),Tbl_Input[Cq])} -> Undetermined | D16: {=_xlfn.XLOOKUP(1,(Tbl_Input[Well Position]='Cq and Delta Cq'!A16)*(Tbl_Input[Reporter]='Cq and Delta Cq'!$D$1),Tbl_Input[Cq])} -> Undetermined | E16: {=_xlfn.XLOOKUP(1,(Tbl_Input[Well Position]='Cq and Delta Cq'!A16)*(Tbl_Input[Reporter]='Cq and Delta Cq'!$E$1),Tbl_Input[Cq])} -> 24.504309 | F16: {=_xlfn.XLOOKUP(1,(Tbl_Input[Well Position]='Cq and Delta Cq'!A16)*(Tbl_Input[Reporter]='Cq and Delta Cq'!$F$1),Tbl_Input[Cq])} -> 28.058144 | G16: {=_xlfn.XLOOKUP(1,(Tbl_Input[Well Position]='Cq and Delta Cq'!A16)*(Tbl_Input[Reporter]='Cq and Delta Cq'!$G$1),Tbl_Input[Cq])} -> 30.281649 | I16: =D16-C16 -> #VALUE! | J16: =G16-F16 -> 2.2235051
A17: ='Data Input'!B89 -> B5 | B17: ='Data Input'!D89 -> OM3-002_120 min | C17: {=_xlfn.XLOOKUP(1,(Tbl_Input[Well Position]='Cq and Delta Cq'!A17)*(Tbl_Input[Reporter]='Cq and Delta Cq'!$C$1),Tbl_Input[Cq])} -> Undetermined | D17: {=_xlfn.XLOOKUP(1,(Tbl_Input[Well Position]='Cq and Delta Cq'!A17)*(Tbl_Input[Reporter]='Cq and Delta Cq'!$D$1),Tbl_Input[Cq])} -> Undetermined | E17: {=_xlfn.XLOOKUP(1,(Tbl_Input[Well Position]='Cq and Delta Cq'!A17)*(Tbl_Input[Reporter]='Cq and Delta Cq'!$E$1),Tbl_Input[Cq])} -> 25.539514 | F17: {=_xlfn.XLOOKUP(1,(Tbl_Input[Well Position]='Cq and Delta Cq'!A17)*(Tbl_Input[Reporter]='Cq and Delta Cq'!$F$1),Tbl_Input[Cq])} -> 28.187706 | G17: {=_xlfn.XLOOKUP(1,(Tbl_Input[Well Position]='Cq and Delta Cq'!A17)*(Tbl_Input[Reporter]='Cq and Delta Cq'!$G$1),Tbl_Input[Cq])} -> 30.731935 | I17: =D17-C17 -> #VALUE! | J17: =G17-F17 -> 2.5442295
A18: ='Data Input'!B94 -> B6 | B18: ='Data Input'!D94 -> OM3-010_0 min | C18: {=_xlfn.XLOOKUP(1,(Tbl_Input[Well Position]='Cq and Delta Cq'!A18)*(Tbl_Input[Reporter]='Cq and Delta Cq'!$C$1),Tbl_Input[Cq])} -> Undetermined | D18: {=_xlfn.XLOOKUP(1,(Tbl_Input[Well Position]='Cq and Delta Cq'!A18)*(Tbl_Input[Reporter]='Cq and Delta Cq'!$D$1),Tbl_Input[Cq])} -> Undetermined | E18: {=_xlfn.XLOOKUP(1,(Tbl_Input[Well Position]='Cq and Delta Cq'!A18)*(Tbl_Input[Reporter]='Cq and Delta Cq'!$E$1),Tbl_Input[Cq])} -> 23.095781 | F18: {=_xlfn.XLOOKUP(1,(Tbl_Input[Well Position]='Cq and Delta Cq'!A18)*(Tbl_Input[Reporter]='Cq and Delta Cq'!$F$1),Tbl_Input[Cq])} -> 30.279534 | G18: {=_xlfn.XLOOKUP(1,(Tbl_Input[Well Position]='Cq and Delta Cq'!A18)*(Tbl_Input[Reporter]='Cq and Delta Cq'!$G$1),Tbl_Input[Cq])} -> 34.217903 | I18: =D18-C18 -> #VALUE! | J18: =G18-F18 -> 3.9383684
A19: ='Data Input'!B99 -> B7 | B19: ='Data Input'!D99 -> OM3-010_5 min | C19: {=_xlfn.XLOOKUP(1,(Tbl_Input[Well Position]='Cq and Delta Cq'!A19)*(Tbl_Input[Reporter]='Cq and Delta Cq'!$C$1),Tbl_Input[Cq])} -> Undetermined | D19: {=_xlfn.XLOOKUP(1,(Tbl_Input[Well Position]='Cq and Delta Cq'!A19)*(Tbl_Input[Reporter]='Cq and Delta Cq'!$D$1),Tbl_Input[Cq])} -> Undetermined | E19: {=_xlfn.XLOOKUP(1,(Tbl_Input[Well Position]='Cq and Delta Cq'!A19)*(Tbl_Input[Reporter]='Cq and Delta Cq'!$E$1),Tbl_Input[Cq])} -> 24.082877 | F19: {=_xlfn.XLOOKUP(1,(Tbl_Input[Well Position]='Cq and Delta Cq'!A19)*(Tbl_Input[Reporter]='Cq and Delta Cq'!$F$1),Tbl_Input[Cq])} -> 31.293727 | G19: {=_xlfn.XLOOKUP(1,(Tbl_Input[Well Position]='Cq and Delta Cq'!A19)*(Tbl_Input[Reporter]='Cq and Delta Cq'!$G$1),Tbl_Input[Cq])} -> 32.931955 | I19: =D19-C19 -> #VALUE! | J19: =G19-F19 -> 1.6382284
A20: ='Data Input'!B104 -> B8 | B20: ='Data Input'!D104 -> OM3-010_30 min | C20: {=_xlfn.XLOOKUP(1,(Tbl_Input[Well Position]='Cq and Delta Cq'!A20)*(Tbl_Input[Reporter]='Cq and Delta Cq'!$C$1),Tbl_Input[Cq])} -> Undetermined | D20: {=_xlfn.XLOOKUP(1,(Tbl_Input[Well Position]='Cq and Delta Cq'!A20)*(Tbl_Input[Reporter]='Cq and Delta Cq'!$D$1),Tbl_Input[Cq])} -> Undetermined | E20: {=_xlfn.XLOOKUP(1,(Tbl_Input[Well Position]='Cq and Delta Cq'!A20)*(Tbl_Input[Reporter]='Cq and Delta Cq'!$E$1),Tbl_Input[Cq])} -> 24.222265 | F20: {=_xlfn.XLOOKUP(1,(Tbl_Input[Well Position]='Cq and Delta Cq'!A20)*(Tbl_Input[Reporter]='Cq and Delta Cq'!$F$1),Tbl_Input[Cq])} -> 32.555615 | G20: {=_xlfn.XLOOKUP(1,(Tbl_Input[Well Position]='Cq and Delta Cq'!A20)*(Tbl_Input[Reporter]='Cq and Delta Cq'!$G$1),Tbl_Input[Cq])} -> 34.895367 | I20: =D20-C20 -> #VALUE! | J20: =G20-F20 -> 2.3397524
A21: ='Data Input'!B109 -> B9 | B21: ='Data Input'!D109 -> OM3-010_60 min | C21: {=_xlfn.XLOOKUP(1,(Tbl_Input[Well Position]='Cq and Delta Cq'!A21)*(Tbl_Input[Reporter]='Cq and Delta Cq'!$C$1),Tbl_Input[Cq])} -> Undetermined | D21: {=_xlfn.XLOOKUP(1,(Tbl_Input[Well Position]='Cq and Delta Cq'!A21)*(Tbl_Input[Reporter]='Cq and Delta Cq'!$D$1),Tbl_Input[Cq])} -> Undetermined | E21: {=_xlfn.XLOOKUP(1,(Tbl_Input[Well Position]='Cq and Delta Cq'!A21)*(Tbl_Input[Reporter]='Cq and Delta Cq'!$E$1),Tbl_Input[Cq])} -> 22.67844 | F21: {=_xlfn.XLOOKUP(1,(Tbl_Input[Well Position]='Cq and Delta Cq'!A21)*(Tbl_Input[Reporter]='Cq and Delta Cq'!$F$1),Tbl_Input[Cq])} -> 29.41659 | G21: {=_xlfn.XLOOKUP(1,(Tbl_Input[Well Position]='Cq and Delta Cq'!A21)*(Tbl_Input[Reporter]='Cq and Delta Cq'!$G$1),Tbl_Input[Cq])} -> 31.292783 | I21: =D21-C21 -> #VALUE! | J21: =G21-F21 -> 1.8761935
A22: ='Data Input'!B114 -> B10 | B22: ='Data Input'!D114 -> OM3-010_120 min | C22: {=_xlfn.XLOOKUP(1,(Tbl_Input[Well Position]='Cq and Delta Cq'!A22)*(Tbl_Input[Reporter]='Cq and Delta Cq'!$C$1),Tbl_Input[Cq])} -> Undetermined | D22: {=_xlfn.XLOOKUP(1,(Tbl_Input[Well Position]='Cq and Delta Cq'!A22)*(Tbl_Input[Reporter]='Cq and Delta Cq'!$D$1),Tbl_Input[Cq])} -> Undetermined | E22: {=_xlfn.XLOOKUP(1,(Tbl_Input[Well Position]='Cq and Delta Cq'!A22)*(Tbl_Input[Reporter]='Cq and Delta Cq'!$E$1),Tbl_Input[Cq])} -> 23.336325 | F22: {=_xlfn.XLOOKUP(1,(Tbl_Input[Well Position]='Cq and Delta Cq'!A22)*(Tbl_Input[Reporter]='Cq and Delta Cq'!$F$1),Tbl_Input[Cq])} -> 31.025138 | G22: {=_xlfn.XLOOKUP(1,(Tbl_Input[Well Position]='Cq and Delta Cq'!A22)*(Tbl_Input[Reporter]='Cq and Delta Cq'!$G$1),Tbl_Input[Cq])} -> 32.729336 | I22: =D22-C22 -> #VALUE! | J22: =G22-F22 -> 1.7041976
A23: ='Data Input'!B119 -> B12 | B23: ='Data Input'!D119 -> NTC | C23: {=_xlfn.XLOOKUP(1,(Tbl_Input[Well Position]='Cq and Delta Cq'!A23)*(Tbl_Input[Reporter]='Cq and Delta Cq'!$C$1),Tbl_Input[Cq])} -> Undetermined | D23: {=_xlfn.XLOOKUP(1,(Tbl_Input[Well Position]='Cq and Delta Cq'!A23)*(Tbl_Input[Reporter]='Cq and Delta Cq'!$D$1),Tbl_Input[Cq])} -> Undetermined | E23: {=_xlfn.XLOOKUP(1,(Tbl_Input[Well Position]='Cq and Delta Cq'!A23)*(Tbl_Input[Reporter]='Cq and Delta Cq'!$E$1),Tbl_Input[Cq])} -> Undetermined | F23: {=_xlfn.XLOOKUP(1,(Tbl_Input[Well Position]='Cq and Delta Cq'!A23)*(Tbl_Input[Reporter]='Cq and Delta Cq'!$F$1),Tbl_Input[Cq])} -> Undetermined | G23: {=_xlfn.XLOOKUP(1,(Tbl_Input[Well Position]='Cq and Delta Cq'!A23)*(Tbl_Input[Reporter]='Cq and Delta Cq'!$G$1),Tbl_Input[Cq])} -> Undetermined | I23: =D23-C23 -> #VALUE! | J23: =G23-F23 -> #VALUE!
A24: ='Data Input'!B124 -> C1 | B24: ='Data Input'!D124 -> OM3-003_0 min | C24: {=_xlfn.XLOOKUP(1,(Tbl_Input[Well Position]='Cq and Delta Cq'!A24)*(Tbl_Input[Reporter]='Cq and Delta Cq'!$C$1),Tbl_Input[Cq])} -> Undetermined | D24: {=_xlfn.XLOOKUP(1,(Tbl_Input[Well Position]='Cq and Delta Cq'!A24)*(Tbl_Input[Reporter]='Cq and Delta Cq'!$D$1),Tbl_Input[Cq])} -> Undetermined | E24: {=_xlfn.XLOOKUP(1,(Tbl_Input[Well Position]='Cq and Delta Cq'!A24)*(Tbl_Input[Reporter]='Cq and Delta Cq'!$E$1),Tbl_Input[Cq])} -> 26.621512 | F24: {=_xlfn.XLOOKUP(1,(Tbl_Input[Well Position]='Cq and Delta Cq'!A24)*(Tbl_Input[Reporter]='Cq and Delta Cq'!$F$1),Tbl_Input[Cq])} -> 35.503399 | G24: {=_xlfn.XLOOKUP(1,(Tbl_Input[Well Position]='Cq and Delta Cq'!A24)*(Tbl_Input[Reporter]='Cq and Delta Cq'!$G$1),Tbl_Input[Cq])} -> Undetermined | I24: =D24-C24 -> #VALUE! | J24: =G24-F24 -> #VALUE!
A25: ='Data Input'!B129 -> C2 | B25: ='Data Input'!D129 -> OM3-003_5 min | C25: {=_xlfn.XLOOKUP(1,(Tbl_Input[Well Position]='Cq and Delta Cq'!A25)*(Tbl_Input[Reporter]='Cq and Delta Cq'!$C$1),Tbl_Input[Cq])} -> Undetermined | D25: {=_xlfn.XLOOKUP(1,(Tbl_Input[Well Position]='Cq and Delta Cq'!A25)*(Tbl_Input[Reporter]='Cq and Delta Cq'!$D$1),Tbl_Input[Cq])} -> Undetermined | E25: {=_xlfn.XLOOKUP(1,(Tbl_Input[Well Position]='Cq and Delta Cq'!A25)*(Tbl_Input[Reporter]='Cq and Delta Cq'!$E$1),Tbl_Input[Cq])} -> 26.958522 | F25: {=_xlfn.XLOOKUP(1,(Tbl_Input[Well Position]='Cq and Delta Cq'!A25)*(Tbl_Input[Reporter]='Cq and Delta Cq'!$F$1),Tbl_Input[Cq])} -> 35.144672 | G25: {=_xlfn.XLOOKUP(1,(Tbl_Input[Well Position]='Cq and Delta Cq'!A25)*(Tbl_Input[Reporter]='Cq and Delta Cq'!$G$1),Tbl_Input[Cq])} -> 40.666512 | I25: =D25-C25 -> #VALUE! | J25: =G25-F25 -> 5.5218406
A26: ='Data Input'!B134 -> C3 | B26: ='Data Input'!D134 -> OM3-003_30 min | C26: {=_xlfn.XLOOKUP(1,(Tbl_Input[Well Position]='Cq and Delta Cq'!A26)*(Tbl_Input[Reporter]='Cq and Delta Cq'!$C$1),Tbl_Input[Cq])} -> Undetermined | D26: {=_xlfn.XLOOKUP(1,(Tbl_Input[Well Position]='Cq and Delta Cq'!A26)*(Tbl_Input[Reporter]='Cq and Delta Cq'!$D$1),Tbl_Input[Cq])} -> Undetermined | E26: {=_xlfn.XLOOKUP(1,(Tbl_Input[Well Position]='Cq and Delta Cq'!A26)*(Tbl_Input[Reporter]='Cq and Delta Cq'!$E$1),Tbl_Input[Cq])} -> 25.943405 | F26: {=_xlfn.XLOOKUP(1,(Tbl_Input[Well Position]='Cq and Delta Cq'!A26)*(Tbl_Input[Reporter]='Cq and Delta Cq'!$F$1),Tbl_Input[Cq])} -> 29.945087 | G26: {=_xlfn.XLOOKUP(1,(Tbl_Input[Well Position]='Cq and Delta Cq'!A26)*(Tbl_Input[Reporter]='Cq and Delta Cq'!$G$1),Tbl_Input[Cq])} -> 33.12238 | I26: =D26-C26 -> #VALUE! | J26: =G26-F26 -> 3.1772934
A27: ='Data Input'!B139 -> C4 | B27: ='Data Input'!D139 -> OM3-003_60 min | C27: {=_xlfn.XLOOKUP(1,(Tbl_Input[Well Position]='Cq and Delta Cq'!A27)*(Tbl_Input[Reporter]='Cq and Delta Cq'!$C$1),Tbl_Input[Cq])} -> Undetermined | D27: {=_xlfn.XLOOKUP(1,(Tbl_Input[Well Position]='Cq and Delta Cq'!A27)*(Tbl_Input[Reporter]='Cq and Delta Cq'!$D$1),Tbl_Input[Cq])} -> Undetermined | E27: {=_xlfn.XLOOKUP(1,(Tbl_Input[Well Position]='Cq and Delta Cq'!A27)*(Tbl_Input[Reporter]='Cq and Delta Cq'!$E$1),Tbl_Input[Cq])} -> 25.638819 | F27: {=_xlfn.XLOOKUP(1,(Tbl_Input[Well Position]='Cq and Delta Cq'!A27)*(Tbl_Input[Reporter]='Cq and Delta Cq'!$F$1),Tbl_Input[Cq])} -> 32.870416 | G27: {=_xlfn.XLOOKUP(1,(Tbl_Input[Well Position]='Cq and Delta Cq'!A27)*(Tbl_Input[Reporter]='Cq and Delta Cq'!$G$1),Tbl_Input[Cq])} -> 40.034604 | I27: =D27-C27 -> #VALUE! | J27: =G27-F27 -> 7.1641873
A28: ='Data Input'!B144 -> C5 | B28: ='Data Input'!D144 -> OM3-003_120 min | C28: {=_xlfn.XLOOKUP(1,(Tbl_Input[Well Position]='Cq and Delta Cq'!A28)*(Tbl_Input[Reporter]='Cq and Delta Cq'!$C$1),Tbl_Input[Cq])} -> Undetermined | D28: {=_xlfn.XLOOKUP(1,(Tbl_Input[Well Position]='Cq and Delta Cq'!A28)*(Tbl_Input[Reporter]='Cq and Delta Cq'!$D$1),Tbl_Input[Cq])} -> Undetermined | E28: {=_xlfn.XLOOKUP(1,(Tbl_Input[Well Position]='Cq and Delta Cq'!A28)*(Tbl_Input[Reporter]='Cq and Delta Cq'!$E$1),Tbl_Input[Cq])} -> 25.436696 | F28: {=_xlfn.XLOOKUP(1,(Tbl_Input[Well Position]='Cq and Delta Cq'!A28)*(Tbl_Input[Reporter]='Cq and Delta Cq'!$F$1),Tbl_Input[Cq])} -> 34.179693 | G28: {=_xlfn.XLOOKUP(1,(Tbl_Input[Well Position]='Cq and Delta Cq'!A28)*(Tbl_Input[Reporter]='Cq and Delta Cq'!$G$1),Tbl_Input[Cq])} -> 38.692706 | I28: =D28-C28 -> #VALUE! | J28: =G28-F28 -> 4.5130132
A29: ='Data Input'!B149 -> C6 | B29: ='Data Input'!D149 -> OM3-011_0 min | C29: {=_xlfn.XLOOKUP(1,(Tbl_Input[Well Position]='Cq and Delta Cq'!A29)*(Tbl_Input[Reporter]='Cq and Delta Cq'!$C$1),Tbl_Input[Cq])} -> Undetermined | D29: {=_xlfn.XLOOKUP(1,(Tbl_Input[Well Position]='Cq and Delta Cq'!A29)*(Tbl_Input[Reporter]='Cq and Delta Cq'!$D$1),Tbl_Input[Cq])} -> Undetermined | E29: {=_xlfn.XLOOKUP(1,(Tbl_Input[Well Position]='Cq and Delta Cq'!A29)*(Tbl_Input[Reporter]='Cq and Delta Cq'!$E$1),Tbl_Input[Cq])} -> 24.239156 | F29: {=_xlfn.XLOOKUP(1,(Tbl_Input[Well Position]='Cq and Delta Cq'!A29)*(Tbl_Input[Reporter]='Cq and Delta Cq'!$F$1),Tbl_Input[Cq])} -> 25.671544 | G29: {=_xlfn.XLOOKUP(1,(Tbl_Input[Well Position]='Cq and Delta Cq'!A29)*(Tbl_Input[Reporter]='Cq and Delta Cq'!$G$1),Tbl_Input[Cq])} -> 28.979223 | I29: =D29-C29 -> #VALUE! | J29: =G29-F29 -> 3.3076794
A30: ='Data Input'!B154 -> C7 | B30: ='Data Input'!D154 -> OM3-011_5 min | C30: {=_xlfn.XLOOKUP(1,(Tbl_Input[Well Position]='Cq and Delta Cq'!A30)*(Tbl_Input[Reporter]='Cq and Delta Cq'!$C$1),Tbl_Input[Cq])} -> Undetermined | D30: {=_xlfn.XLOOKUP(1,(Tbl_Input[Well Position]='Cq and Delta Cq'!A30)*(Tbl_Input[Reporter]='Cq and Delta Cq'!$D$1),Tbl_Input[Cq])} -> Undetermined | E30: {=_xlfn.XLOOKUP(1,(Tbl_Input[Well Position]='Cq and Delta Cq'!A30)*(Tbl_Input[Reporter]='Cq and Delta Cq'!$E$1),Tbl_Input[Cq])} -> 26.954757 | F30: {=_xlfn.XLOOKUP(1,(Tbl_Input[Well Position]='Cq and Delta Cq'!A30)*(Tbl_Input[Reporter]='Cq and Delta Cq'!$F$1),Tbl_Input[Cq])} -> 28.768662 | G30: {=_xlfn.XLOOKUP(1,(Tbl_Input[Well Position]='Cq and Delta Cq'!A30)*(Tbl_Input[Reporter]='Cq and Delta Cq'!$G$1),Tbl_Input[Cq])} -> 30.930132 | I30: =D30-C30 -> #VALUE! | J30: =G30-F30 -> 2.1614704
A31: ='Data Input'!B159 -> C8 | B31: ='Data Input'!D159 -> OM3-011_30 min | C31: {=_xlfn.XLOOKUP(1,(Tbl_Input[Well Position]='Cq and Delta Cq'!A31)*(Tbl_Input[Reporter]='Cq and Delta Cq'!$C$1),Tbl_Input[Cq])} -> Undetermined | D31: {=_xlfn.XLOOKUP(1,(Tbl_Input[Well Position]='Cq and Delta Cq'!A31)*(Tbl_Input[Reporter]='Cq and Delta Cq'!$D$1),Tbl_Input[Cq])} -> Undetermined | E31: {=_xlfn.XLOOKUP(1,(Tbl_Input[Well Position]='Cq and Delta Cq'!A31)*(Tbl_Input[Reporter]='Cq and Delta Cq'!$E$1),Tbl_Input[Cq])} -> 25.404729 | F31: {=_xlfn.XLOOKUP(1,(Tbl_Input[Well Position]='Cq and Delta Cq'!A31)*(Tbl_Input[Reporter]='Cq and Delta Cq'!$F$1),Tbl_Input[Cq])} -> 27.949954 | G31: {=_xlfn.XLOOKUP(1,(Tbl_Input[Well Position]='Cq and Delta Cq'!A31)*(Tbl_Input[Reporter]='Cq and Delta Cq'!$G$1),Tbl_Input[Cq])} -> 31.329802 | I31: =D31-C31 -> #VALUE! | J31: =G31-F31 -> 3.3798482
A32: ='Data Input'!B164 -> C9 | B32: ='Data Input'!D164 -> OM3-011_60 min | C32: {=_xlfn.XLOOKUP(1,(Tbl_Input[Well Position]='Cq and Delta Cq'!A32)*(Tbl_Input[Reporter]='Cq and Delta Cq'!$C$1),Tbl_Input[Cq])} -> Undetermined | D32: {=_xlfn.XLOOKUP(1,(Tbl_Input[Well Position]='Cq and Delta Cq'!A32)*(Tbl_Input[Reporter]='Cq and Delta Cq'!$D$1),Tbl_Input[Cq])} -> Undetermined | E32: {=_xlfn.XLOOKUP(1,(Tbl_Input[Well Position]='Cq and Delta Cq'!A32)*(Tbl_Input[Reporter]='Cq and Delta Cq'!$E$1),Tbl_Input[Cq])} -> 27.243513 | F32: {=_xlfn.XLOOKUP(1,(Tbl_Input[Well Position]='Cq and Delta Cq'!A32)*(Tbl_Input[Reporter]='Cq and Delta Cq'!$F$1),Tbl_Input[Cq])} -> 31.007634 | G32: {=_xlfn.XLOOKUP(1,(Tbl_Input[Well Position]='Cq and Delta Cq'!A32)*(Tbl_Input[Reporter]='Cq and Delta Cq'!$G$1),Tbl_Input[Cq])} -> 33.220777 | I32: =D32-C32 -> #VALUE! | J32: =G32-F32 -> 2.213143
A33: ='Data Input'!B169 -> C10 | B33: ='Data Input'!D169 -> OM3-011_120 min | C33: {=_xlfn.XLOOKUP(1,(Tbl_Input[Well Position]='Cq and Delta Cq'!A33)*(Tbl_Input[Reporter]='Cq and Delta Cq'!$C$1),Tbl_Input[Cq])} -> Undetermined | D33: {=_xlfn.XLOOKUP(1,(Tbl_Input[Well Position]='Cq and Delta Cq'!A33)*(Tbl_Input[Reporter]='Cq and Delta Cq'!$D$1),Tbl_Input[Cq])} -> Undetermined | E33: {=_xlfn.XLOOKUP(1,(Tbl_Input[Well Position]='Cq and Delta Cq'!A33)*(Tbl_Input[Reporter]='Cq and Delta Cq'!$E$1),Tbl_Input[Cq])} -> 26.654273 | F33: {=_xlfn.XLOOKUP(1,(Tbl_Input[Well Position]='Cq and Delta Cq'!A33)*(Tbl_Input[Reporter]='Cq and Delta Cq'!$F$1),Tbl_Input[Cq])} -> 33.942958 | G33: {=_xlfn.XLOOKUP(1,(Tbl_Input[Well Position]='Cq and Delta Cq'!A33)*(Tbl_Input[Reporter]='Cq and Delta Cq'!$G$1),Tbl_Input[Cq])} -> Undetermined | I33: =D33-C33 -> #VALUE! | J33: =G33-F33 -> #VALUE!
A34: ='Data Input'!B174 -> C12 | B34: ='Data Input'!D174 -> CT/NG gblock | C34: {=_xlfn.XLOOKUP(1,(Tbl_Input[Well Position]='Cq and Delta Cq'!A34)*(Tbl_Input[Reporter]='Cq and Delta Cq'!$C$1),Tbl_Input[Cq])} -> 27.757596 | D34: {=_xlfn.XLOOKUP(1,(Tbl_Input[Well Position]='Cq and Delta Cq'!A34)*(Tbl_Input[Reporter]='Cq and Delta Cq'!$D$1),Tbl_Input[Cq])} -> 28.652821 | E34: {=_xlfn.XLOOKUP(1,(Tbl_Input[Well Position]='Cq and Delta Cq'!A34)*(Tbl_Input[Reporter]='Cq and Delta Cq'!$E$1),Tbl_Input[Cq])} -> Undetermined | F34: {=_xlfn.XLOOKUP(1,(Tbl_Input[Well Position]='Cq and Delta Cq'!A34)*(Tbl_Input[Reporter]='Cq and Delta Cq'!$F$1),Tbl_Input[Cq])} -> 27.407102 | G34: {=_xlfn.XLOOKUP(1,(Tbl_Input[Well Position]='Cq and Delta Cq'!A34)*(Tbl_Input[Reporter]='Cq and Delta Cq'!$G$1),Tbl_Input[Cq])} -> 28.598585 | I34: =D34-C34 -> 0.89522555 | J34: =G34-F34 -> 1.1914832
A35: ='Data Input'!B179 -> D1 | B35: ='Data Input'!D179 -> OM3-004_0 min | C35: {=_xlfn.XLOOKUP(1,(Tbl_Input[Well Position]='Cq and Delta Cq'!A35)*(Tbl_Input[Reporter]='Cq and Delta Cq'!$C$1),Tbl_Input[Cq])} -> Undetermined | D35: {=_xlfn.XLOOKUP(1,(Tbl_Input[Well Position]='Cq and Delta Cq'!A35)*(Tbl_Input[Reporter]='Cq and Delta Cq'!$D$1),Tbl_Input[Cq])} -> Undetermined | E35: {=_xlfn.XLOOKUP(1,(Tbl_Input[Well Position]='Cq and Delta Cq'!A35)*(Tbl_Input[Reporter]='Cq and Delta Cq'!$E$1),Tbl_Input[Cq])} -> 25.729278 | F35: {=_xlfn.XLOOKUP(1,(Tbl_Input[Well Position]='Cq and Delta Cq'!A35)*(Tbl_Input[Reporter]='Cq and Delta Cq'!$F$1),Tbl_Input[Cq])} -> 27.838616 | G35: {=_xlfn.XLOOKUP(1,(Tbl_Input[Well Position]='Cq and Delta Cq'!A35)*(Tbl_Input[Reporter]='Cq and Delta Cq'!$G$1),Tbl_Input[Cq])} -> 29.748731 | I35: =D35-C35 -> #VALUE! | J35: =G35-F35 -> 1.9101142
A36: ='Data Input'!B184 -> D2 | B36: ='Data Input'!D184 -> OM3-004_5 min | C36: {=_xlfn.XLOOKUP(1,(Tbl_Input[Well Position]='Cq and Delta Cq'!A36)*(Tbl_Input[Reporter]='Cq and Delta Cq'!$C$1),Tbl_Input[Cq])} -> Undetermined | D36: {=_xlfn.XLOOKUP(1,(Tbl_Input[Well Position]='Cq and Delta Cq'!A36)*(Tbl_Input[Reporter]='Cq and Delta Cq'!$D$1),Tbl_Input[Cq])} -> Undetermined | E36: {=_xlfn.XLOOKUP(1,(Tbl_Input[Well Position]='Cq and Delta Cq'!A36)*(Tbl_Input[Reporter]='Cq and Delta Cq'!$E$1),Tbl_Input[Cq])} -> 25.995508 | F36: {=_xlfn.XLOOKUP(1,(Tbl_Input[Well Position]='Cq and Delta Cq'!A36)*(Tbl_Input[Reporter]='Cq and Delta Cq'!$F$1),Tbl_Input[Cq])} -> 28.453334 | G36: {=_xlfn.XLOOKUP(1,(Tbl_Input[Well Position]='Cq and Delta Cq'!A36)*(Tbl_Input[Reporter]='Cq and Delta Cq'!$G$1),Tbl_Input[Cq])} -> 30.925166 | I36: =D36-C36 -> #VALUE! | J36: =G36-F36 -> 2.4718325
A37: ='Data Input'!B189 -> D3 | B37: ='Data Input'!D189 -> OM3-004_30 min | C37: {=_xlfn.XLOOKUP(1,(Tbl_Input[Well Position]='Cq and Delta Cq'!A37)*(Tbl_Input[Reporter]='Cq and Delta Cq'!$C$1),Tbl_Input[Cq])} -> Undetermined | D37: {=_xlfn.XLOOKUP(1,(Tbl_Input[Well Position]='Cq and Delta Cq'!A37)*(Tbl_Input[Reporter]='Cq and Delta Cq'!$D$1),Tbl_Input[Cq])} -> Undetermined | E37: {=_xlfn.XLOOKUP(1,(Tbl_Input[Well Position]='Cq and Delta Cq'!A37)*(Tbl_Input[Reporter]='Cq and Delta Cq'!$E$1),Tbl_Input[Cq])} -> 25.12052 | F37: {=_xlfn.XLOOKUP(1,(Tbl_Input[Well Position]='Cq and Delta Cq'!A37)*(Tbl_Input[Reporter]='Cq and Delta Cq'!$F$1),Tbl_Input[Cq])} -> 28.699967 | G37: {=_xlfn.XLOOKUP(1,(Tbl_Input[Well Position]='Cq and Delta Cq'!A37)*(Tbl_Input[Reporter]='Cq and Delta Cq'!$G$1),Tbl_Input[Cq])} -> 31.096763 | I37: =D37-C37 -> #VALUE! | J37: =G37-F37 -> 2.3967956
A38: ='Data Input'!B194 -> D4 | B38: ='Data Input'!D194 -> OM3-004_60 min | C38: {=_xlfn.XLOOKUP(1,(Tbl_Input[Well Position]='Cq and Delta Cq'!A38)*(Tbl_Input[Reporter]='Cq and Delta Cq'!$C$1),Tbl_Input[Cq])} -> Undetermined | D38: {=_xlfn.XLOOKUP(1,(Tbl_Input[Well Position]='Cq and Delta Cq'!A38)*(Tbl_Input[Reporter]='Cq and Delta Cq'!$D$1),Tbl_Input[Cq])} -> Undetermined | E38: {=_xlfn.XLOOKUP(1,(Tbl_Input[Well Position]='Cq and Delta Cq'!A38)*(Tbl_Input[Reporter]='Cq and Delta Cq'!$E$1),Tbl_Input[Cq])} -> 26.947432 | F38: {=_xlfn.XLOOKUP(1,(Tbl_Input[Well Position]='Cq and Delta Cq'!A38)*(Tbl_Input[Reporter]='Cq and Delta Cq'!$F$1),Tbl_Input[Cq])} -> 28.991617 | G38: {=_xlfn.XLOOKUP(1,(Tbl_Input[Well Position]='Cq and Delta Cq'!A38)*(Tbl_Input[Reporter]='Cq and Delta Cq'!$G$1),Tbl_Input[Cq])} -> 31.001294 | I38: =D38-C38 -> #VALUE! | J38: =G38-F38 -> 2.0096766
A39: ='Data Input'!B199 -> D5 | B39: ='Data Input'!D199 -> OM3-004_120 min | C39: {=_xlfn.XLOOKUP(1,(Tbl_Input[Well Position]='Cq and Delta Cq'!A39)*(Tbl_Input[Reporter]='Cq and Delta Cq'!$C$1),Tbl_Input[Cq])} -> Undetermined | D39: {=_xlfn.XLOOKUP(1,(Tbl_Input[Well Position]='Cq and Delta Cq'!A39)*(Tbl_Input[Reporter]='Cq and Delta Cq'!$D$1),Tbl_Input[Cq])} -> Undetermined | E39: {=_xlfn.XLOOKUP(1,(Tbl_Input[Well Position]='Cq and Delta Cq'!A39)*(Tbl_Input[Reporter]='Cq and Delta Cq'!$E$1),Tbl_Input[Cq])} -> 26.183358 | F39: {=_xlfn.XLOOKUP(1,(Tbl_Input[Well Position]='Cq and Delta Cq'!A39)*(Tbl_Input[Reporter]='Cq and Delta Cq'!$F$1),Tbl_Input[Cq])} -> 27.740959 | G39: {=_xlfn.XLOOKUP(1,(Tbl_Input[Well Position]='Cq and Delta Cq'!A39)*(Tbl_Input[Reporter]='Cq and Delta Cq'!$G$1),Tbl_Input[Cq])} -> 30.089038 | I39: =D39-C39 -> #VALUE! | J39: =G39-F39 -> 2.3480794
A40: ='Data Input'!B204 -> D6 | B40: ='Data Input'!D204 -> OM3-012_0 min | C40: {=_xlfn.XLOOKUP(1,(Tbl_Input[Well Position]='Cq and Delta Cq'!A40)*(Tbl_Input[Reporter]='Cq and Delta Cq'!$C$1),Tbl_Input[Cq])} -> Undetermined | D40: {=_xlfn.XLOOKUP(1,(Tbl_Input[Well Position]='Cq and Delta Cq'!A40)*(Tbl_Input[Reporter]='Cq and Delta Cq'!$D$1),Tbl_Input[Cq])} -> Undetermined | E40: {=_xlfn.XLOOKUP(1,(Tbl_Input[Well Position]='Cq and Delta Cq'!A40)*(Tbl_Input[Reporter]='Cq and Delta Cq'!$E$1),Tbl_Input[Cq])} -> 23.562878 | F40: {=_xlfn.XLOOKUP(1,(Tbl_Input[Well Position]='Cq and Delta Cq'!A40)*(Tbl_Input[Reporter]='Cq and Delta Cq'!$F$1),Tbl_Input[Cq])} -> 31.628879 | G40: {=_xlfn.XLOOKUP(1,(Tbl_Input[Well Position]='Cq and Delta Cq'!A40)*(Tbl_Input[Reporter]='Cq and Delta Cq'!$G$1),Tbl_Input[Cq])} -> 34.440484 | I40: =D40-C40 -> #VALUE! | J40: =G40-F40 -> 2.8116051
...

Sheet VITA Index summary
A4: Position | B4: Sample Name | C4: CT target | D4: CT VITA Index | E4: CT Viability Threshold | F4: NG target | G4: NG VITA Index | H4: NG Viability Threshold | I4: Endogenous Control
A5: ='Cq and Delta Cq'!A2 -> A1 | B5: ='Cq and Delta Cq'!B2 -> OM3-001_0 min | C5: =IF(OR(AND('Cq and Delta Cq'!C2>'VITA Index summary'!$O$15,'Cq and Delta Cq'!C2<'VITA Index summary'!$O$16),AND('Cq and Delta Cq'!D2>'VITA Index summary'!$O$21,'Cq and Delta Cq'!D2<'VITA Index summary'!$O$22)),"CT detected", "CT not detected") -> CT not detected | D5: {=IFERROR(_xlfn.IFS(C5="CT not detected","N/A",'Cq and Delta Cq'!C2>'VITA Index summary'!$T$16,"Indeterminate",'Cq and Delta Cq'!D2>'VITA Index summary'!$T$22,"Indeterminate",'Cq and Delta Cq'!C2<'VITA Index summary'!$T$16,2^('Cq and Delta Cq'!I2)/2,'Cq and Delta Cq'!D2<'VITA Index summary'!$T$22,2^('Cq and Delta Cq'!I2)/2),"Indeterminate")} -> N/A | E5: =$O$8 -> 1.57 | F5: =IF(OR(AND('Cq and Delta Cq'!F2>'VITA Index summary'!$O$27,'Cq and Delta Cq'!F2<'VITA Index summary'!$O$28),AND('Cq and Delta Cq'!G2>'VITA Index summary'!$O$33,'Cq and Delta Cq'!G2<'VITA Index summary'!$O$34)),"NG detected", "NG not detected") -> NG detected | G5: {=IFERROR(_xlfn.IFS(F5="NG not detected","N/A",'Cq and Delta Cq'!F2>'VITA Index summary'!$T$28,"Indeterminate",'Cq and Delta Cq'!G2>'VITA Index summary'!$T$34,"Indeterminate",'Cq and Delta Cq'!F2<'VITA Index summary'!$T$28,2^('Cq and Delta Cq'!J2)/2,'Cq and Delta Cq'!G2<'VITA Index summary'!$T$34,2^('Cq and Delta Cq'!J2)/2),"Indeterminate")} -> Indeterminate | H5: =$O$7 -> 1.46 | I5: =IFERROR(IF(AND('VITA Index summary'!$O$39<'Cq and Delta Cq'!E2,'Cq and Delta Cq'!E2<'VITA Index summary'!$O$40),"EC VALID","EC INVALID"),"EC INVALID") -> EC VALID
A6: ='Cq and Delta Cq'!A3 -> A2 | B6: ='Cq and Delta Cq'!B3 -> OM3-001_5 min | C6: =IF(OR(AND('Cq and Delta Cq'!C3>'VITA Index summary'!$O$15,'Cq and Delta Cq'!C3<'VITA Index summary'!$O$16),AND('Cq and Delta Cq'!D3>'VITA Index summary'!$O$21,'Cq and Delta Cq'!D3<'VITA Index summary'!$O$22)),"CT detected", "CT not detected") -> CT not detected | D6: {=IFERROR(_xlfn.IFS(C6="CT not detected","N/A",'Cq and Delta Cq'!C3>'VITA Index summary'!$T$16,"Indeterminate",'Cq and Delta Cq'!D3>'VITA Index summary'!$T$22,"Indeterminate",'Cq and Delta Cq'!C3<'VITA Index summary'!$T$16,2^('Cq and Delta Cq'!I3)/2,'Cq and Delta Cq'!D3<'VITA Index summary'!$T$22,2^('Cq and Delta Cq'!I3)/2),"Indeterminate")} -> N/A | E6: =$O$8 -> 1.57 | F6: =IF(OR(AND('Cq and Delta Cq'!F3>'VITA Index summary'!$O$27,'Cq and Delta Cq'!F3<'VITA Index summary'!$O$28),AND('Cq and Delta Cq'!G3>'VITA Index summary'!$O$33,'Cq and Delta Cq'!G3<'VITA Index summary'!$O$34)),"NG detected", "NG not detected") -> NG detected | G6: {=IFERROR(_xlfn.IFS(F6="NG not detected","N/A",'Cq and Delta Cq'!F3>'VITA Index summary'!$T$28,"Indeterminate",'Cq and Delta Cq'!G3>'VITA Index summary'!$T$34,"Indeterminate",'Cq and Delta Cq'!F3<'VITA Index summary'!$T$28,2^('Cq and Delta Cq'!J3)/2,'Cq and Delta Cq'!G3<'VITA Index summary'!$T$34,2^('Cq and Delta Cq'!J3)/2),"Indeterminate")} -> Indeterminate | H6: =$O$7 -> 1.46 | I6: =IFERROR(IF(AND('VITA Index summary'!$O$39<'Cq and Delta Cq'!E3,'Cq and Delta Cq'!E3<'VITA Index summary'!$O$40),"EC VALID","EC INVALID"),"EC INVALID") -> EC VALID | N6: Viability Threshold
A7: ='Cq and Delta Cq'!A4 -> A3 | B7: ='Cq and Delta Cq'!B4 -> OM3-001_30 min | C7: =IF(OR(AND('Cq and Delta Cq'!C4>'VITA Index summary'!$O$15,'Cq and Delta Cq'!C4<'VITA Index summary'!$O$16),AND('Cq and Delta Cq'!D4>'VITA Index summary'!$O$21,'Cq and Delta Cq'!D4<'VITA Index summary'!$O$22)),"CT detected", "CT not detected") -> CT not detected | D7: {=IFERROR(_xlfn.IFS(C7="CT not detected","N/A",'Cq and Delta Cq'!C4>'VITA Index summary'!$T$16,"Indeterminate",'Cq and Delta Cq'!D4>'VITA Index summary'!$T$22,"Indeterminate",'Cq and Delta Cq'!C4<'VITA Index summary'!$T$16,2^('Cq and Delta Cq'!I4)/2,'Cq and Delta Cq'!D4<'VITA Index summary'!$T$22,2^('Cq and Delta Cq'!I4)/2),"Indeterminate")} -> N/A | E7: =$O$8 -> 1.57 | F7: =IF(OR(AND('Cq and Delta Cq'!F4>'VITA Index summary'!$O$27,'Cq and Delta Cq'!F4<'VITA Index summary'!$O$28),AND('Cq and Delta Cq'!G4>'VITA Index summary'!$O$33,'Cq and Delta Cq'!G4<'VITA Index summary'!$O$34)),"NG detected", "NG not detected") -> NG detected | G7: {=IFERROR(_xlfn.IFS(F7="NG not detected","N/A",'Cq and Delta Cq'!F4>'VITA Index summary'!$T$28,"Indeterminate",'Cq and Delta Cq'!G4>'VITA Index summary'!$T$34,"Indeterminate",'Cq and Delta Cq'!F4<'VITA Index summary'!$T$28,2^('Cq and Delta Cq'!J4)/2,'Cq and Delta Cq'!G4<'VITA Index summary'!$T$34,2^('Cq and Delta Cq'!J4)/2),"Indeterminate")} -> Indeterminate | H7: =$O$7 -> 1.46 | I7: =IFERROR(IF(AND('VITA Index summary'!$O$39<'Cq and Delta Cq'!E4,'Cq and Delta Cq'!E4<'VITA Index summary'!$O$40),"EC VALID","EC INVALID"),"EC INVALID") -> EC VALID | N7: NG | O7: 1.46
A8: ='Cq and Delta Cq'!A5 -> A4 | B8: ='Cq and Delta Cq'!B5 -> OM3-001_60 min | C8: =IF(OR(AND('Cq and Delta Cq'!C5>'VITA Index summary'!$O$15,'Cq and Delta Cq'!C5<'VITA Index summary'!$O$16),AND('Cq and Delta Cq'!D5>'VITA Index summary'!$O$21,'Cq and Delta Cq'!D5<'VITA Index summary'!$O$22)),"CT detected", "CT not detected") -> CT not detected | D8: {=IFERROR(_xlfn.IFS(C8="CT not detected","N/A",'Cq and Delta Cq'!C5>'VITA Index summary'!$T$16,"Indeterminate",'Cq and Delta Cq'!D5>'VITA Index summary'!$T$22,"Indeterminate",'Cq and Delta Cq'!C5<'VITA Index summary'!$T$16,2^('Cq and Delta Cq'!I5)/2,'Cq and Delta Cq'!D5<'VITA Index summary'!$T$22,2^('Cq and Delta Cq'!I5)/2),"Indeterminate")} -> N/A | E8: =$O$8 -> 1.57 | F8: =IF(OR(AND('Cq and Delta Cq'!F5>'VITA Index summary'!$O$27,'Cq and Delta Cq'!F5<'VITA Index summary'!$O$28),AND('Cq and Delta Cq'!G5>'VITA Index summary'!$O$33,'Cq and Delta Cq'!G5<'VITA Index summary'!$O$34)),"NG detected", "NG not detected") -> NG detected | G8: {=IFERROR(_xlfn.IFS(F8="NG not detected","N/A",'Cq and Delta Cq'!F5>'VITA Index summary'!$T$28,"Indeterminate",'Cq and Delta Cq'!G5>'VITA Index summary'!$T$34,"Indeterminate",'Cq and Delta Cq'!F5<'VITA Index summary'!$T$28,2^('Cq and Delta Cq'!J5)/2,'Cq and Delta Cq'!G5<'VITA Index summary'!$T$34,2^('Cq and Delta Cq'!J5)/2),"Indeterminate")} -> Indeterminate | H8: =$O$7 -> 1.46 | I8: =IFERROR(IF(AND('VITA Index summary'!$O$39<'Cq and Delta Cq'!E5,'Cq and Delta Cq'!E5<'VITA Index summary'!$O$40),"EC VALID","EC INVALID"),"EC INVALID") -> EC VALID | N8: CT | O8: 1.57
A9: ='Cq and Delta Cq'!A6 -> A5 | B9: ='Cq and Delta Cq'!B6 -> OM3-001_120 min | C9: =IF(OR(AND('Cq and Delta Cq'!C6>'VITA Index summary'!$O$15,'Cq and Delta Cq'!C6<'VITA Index summary'!$O$16),AND('Cq and Delta Cq'!D6>'VITA Index summary'!$O$21,'Cq and Delta Cq'!D6<'VITA Index summary'!$O$22)),"CT detected", "CT not detected") -> CT not detected | D9: {=IFERROR(_xlfn.IFS(C9="CT not detected","N/A",'Cq and Delta Cq'!C6>'VITA Index summary'!$T$16,"Indeterminate",'Cq and Delta Cq'!D6>'VITA Index summary'!$T$22,"Indeterminate",'Cq and Delta Cq'!C6<'VITA Index summary'!$T$16,2^('Cq and Delta Cq'!I6)/2,'Cq and Delta Cq'!D6<'VITA Index summary'!$T$22,2^('Cq and Delta Cq'!I6)/2),"Indeterminate")} -> N/A | E9: =$O$8 -> 1.57 | F9: =IF(OR(AND('Cq and Delta Cq'!F6>'VITA Index summary'!$O$27,'Cq and Delta Cq'!F6<'VITA Index summary'!$O$28),AND('Cq and Delta Cq'!G6>'VITA Index summary'!$O$33,'Cq and Delta Cq'!G6<'VITA Index summary'!$O$34)),"NG detected", "NG not detected") -> NG detected | G9: {=IFERROR(_xlfn.IFS(F9="NG not detected","N/A",'Cq and Delta Cq'!F6>'VITA Index summary'!$T$28,"Indeterminate",'Cq and Delta Cq'!G6>'VITA Index summary'!$T$34,"Indeterminate",'Cq and Delta Cq'!F6<'VITA Index summary'!$T$28,2^('Cq and Delta Cq'!J6)/2,'Cq and Delta Cq'!G6<'VITA Index summary'!$T$34,2^('Cq and Delta Cq'!J6)/2),"Indeterminate")} -> 4.2128058 | H9: =$O$7 -> 1.46 | I9: =IFERROR(IF(AND('VITA Index summary'!$O$39<'Cq and Delta Cq'!E6,'Cq and Delta Cq'!E6<'VITA Index summary'!$O$40),"EC VALID","EC INVALID"),"EC INVALID") -> EC VALID
A10: ='Cq and Delta Cq'!A7 -> A6 | B10: ='Cq and Delta Cq'!B7 -> OM3-009_0 min | C10: =IF(OR(AND('Cq and Delta Cq'!C7>'VITA Index summary'!$O$15,'Cq and Delta Cq'!C7<'VITA Index summary'!$O$16),AND('Cq and Delta Cq'!D7>'VITA Index summary'!$O$21,'Cq and Delta Cq'!D7<'VITA Index summary'!$O$22)),"CT detected", "CT not detected") -> CT not detected | D10: {=IFERROR(_xlfn.IFS(C10="CT not detected","N/A",'Cq and Delta Cq'!C7>'VITA Index summary'!$T$16,"Indeterminate",'Cq and Delta Cq'!D7>'VITA Index summary'!$T$22,"Indeterminate",'Cq and Delta Cq'!C7<'VITA Index summary'!$T$16,2^('Cq and Delta Cq'!I7)/2,'Cq and Delta Cq'!D7<'VITA Index summary'!$T$22,2^('Cq and Delta Cq'!I7)/2),"Indeterminate")} -> N/A | E10: =$O$8 -> 1.57 | F10: =IF(OR(AND('Cq and Delta Cq'!F7>'VITA Index summary'!$O$27,'Cq and Delta Cq'!F7<'VITA Index summary'!$O$28),AND('Cq and Delta Cq'!G7>'VITA Index summary'!$O$33,'Cq and Delta Cq'!G7<'VITA Index summary'!$O$34)),"NG detected", "NG not detected") -> NG not detected | G10: {=IFERROR(_xlfn.IFS(F10="NG not detected","N/A",'Cq and Delta Cq'!F7>'VITA Index summary'!$T$28,"Indeterminate",'Cq and Delta Cq'!G7>'VITA Index summary'!$T$34,"Indeterminate",'Cq and Delta Cq'!F7<'VITA Index summary'!$T$28,2^('Cq and Delta Cq'!J7)/2,'Cq and Delta Cq'!G7<'VITA Index summary'!$T$34,2^('Cq and Delta Cq'!J7)/2),"Indeterminate")} -> N/A | H10: =$O$7 -> 1.46 | I10: =IFERROR(IF(AND('VITA Index summary'!$O$39<'Cq and Delta Cq'!E7,'Cq and Delta Cq'!E7<'VITA Index summary'!$O$40),"EC VALID","EC INVALID"),"EC INVALID") -> EC VALID
A11: ='Cq and Delta Cq'!A8 -> A7 | B11: ='Cq and Delta Cq'!B8 -> OM3-009_5 min | C11: =IF(OR(AND('Cq and Delta Cq'!C8>'VITA Index summary'!$O$15,'Cq and Delta Cq'!C8<'VITA Index summary'!$O$16),AND('Cq and Delta Cq'!D8>'VITA Index summary'!$O$21,'Cq and Delta Cq'!D8<'VITA Index summary'!$O$22)),"CT detected", "CT not detected") -> CT not detected | D11: {=IFERROR(_xlfn.IFS(C11="CT not detected","N/A",'Cq and Delta Cq'!C8>'VITA Index summary'!$T$16,"Indeterminate",'Cq and Delta Cq'!D8>'VITA Index summary'!$T$22,"Indeterminate",'Cq and Delta Cq'!C8<'VITA Index summary'!$T$16,2^('Cq and Delta Cq'!I8)/2,'Cq and Delta Cq'!D8<'VITA Index summary'!$T$22,2^('Cq and Delta Cq'!I8)/2),"Indeterminate")} -> N/A | E11: =$O$8 -> 1.57 | F11: =IF(OR(AND('Cq and Delta Cq'!F8>'VITA Index summary'!$O$27,'Cq and Delta Cq'!F8<'VITA Index summary'!$O$28),AND('Cq and Delta Cq'!G8>'VITA Index summary'!$O$33,'Cq and Delta Cq'!G8<'VITA Index summary'!$O$34)),"NG detected", "NG not detected") -> NG not detected | G11: {=IFERROR(_xlfn.IFS(F11="NG not detected","N/A",'Cq and Delta Cq'!F8>'VITA Index summary'!$T$28,"Indeterminate",'Cq and Delta Cq'!G8>'VITA Index summary'!$T$34,"Indeterminate",'Cq and Delta Cq'!F8<'VITA Index summary'!$T$28,2^('Cq and Delta Cq'!J8)/2,'Cq and Delta Cq'!G8<'VITA Index summary'!$T$34,2^('Cq and Delta Cq'!J8)/2),"Indeterminate")} -> N/A | H11: =$O$7 -> 1.46 | I11: =IFERROR(IF(AND('VITA Index summary'!$O$39<'Cq and Delta Cq'!E8,'Cq and Delta Cq'!E8<'VITA Index summary'!$O$40),"EC VALID","EC INVALID"),"EC INVALID") -> EC VALID
A12: ='Cq and Delta Cq'!A9 -> A8 | B12: ='Cq and Delta Cq'!B9 -> OM3-009_30 min | C12: =IF(OR(AND('Cq and Delta Cq'!C9>'VITA Index summary'!$O$15,'Cq and Delta Cq'!C9<'VITA Index summary'!$O$16),AND('Cq and Delta Cq'!D9>'VITA Index summary'!$O$21,'Cq and Delta Cq'!D9<'VITA Index summary'!$O$22)),"CT detected", "CT not detected") -> CT not detected | D12: {=IFERROR(_xlfn.IFS(C12="CT not detected","N/A",'Cq and Delta Cq'!C9>'VITA Index summary'!$T$16,"Indeterminate",'Cq and Delta Cq'!D9>'VITA Index summary'!$T$22,"Indeterminate",'Cq and Delta Cq'!C9<'VITA Index summary'!$T$16,2^('Cq and Delta Cq'!I9)/2,'Cq and Delta Cq'!D9<'VITA Index summary'!$T$22,2^('Cq and Delta Cq'!I9)/2),"Indeterminate")} -> N/A | E12: =$O$8 -> 1.57 | F12: =IF(OR(AND('Cq and Delta Cq'!F9>'VITA Index summary'!$O$27,'Cq and Delta Cq'!F9<'VITA Index summary'!$O$28),AND('Cq and Delta Cq'!G9>'VITA Index summary'!$O$33,'Cq and Delta Cq'!G9<'VITA Index summary'!$O$34)),"NG detected", "NG not detected") -> NG detected | G12: {=IFERROR(_xlfn.IFS(F12="NG not detected","N/A",'Cq and Delta Cq'!F9>'VITA Index summary'!$T$28,"Indeterminate",'Cq and Delta Cq'!G9>'VITA Index summary'!$T$34,"Indeterminate",'Cq and Delta Cq'!F9<'VITA Index summary'!$T$28,2^('Cq and Delta Cq'!J9)/2,'Cq and Delta Cq'!G9<'VITA Index summary'!$T$34,2^('Cq and Delta Cq'!J9)/2),"Indeterminate")} -> Indeterminate | H12: =$O$7 -> 1.46 | I12: =IFERROR(IF(AND('VITA Index summary'!$O$39<'Cq and Delta Cq'!E9,'Cq and Delta Cq'!E9<'VITA Index summary'!$O$40),"EC VALID","EC INVALID"),"EC INVALID") -> EC VALID
A13: ='Cq and Delta Cq'!A10 -> A9 | B13: ='Cq and Delta Cq'!B10 -> OM3-009_60 min | C13: =IF(OR(AND('Cq and Delta Cq'!C10>'VITA Index summary'!$O$15,'Cq and Delta Cq'!C10<'VITA Index summary'!$O$16),AND('Cq and Delta Cq'!D10>'VITA Index summary'!$O$21,'Cq and Delta Cq'!D10<'VITA Index summary'!$O$22)),"CT detected", "CT not detected") -> CT not detected | D13: {=IFERROR(_xlfn.IFS(C13="CT not detected","N/A",'Cq and Delta Cq'!C10>'VITA Index summary'!$T$16,"Indeterminate",'Cq and Delta Cq'!D10>'VITA Index summary'!$T$22,"Indeterminate",'Cq and Delta Cq'!C10<'VITA Index summary'!$T$16,2^('Cq and Delta Cq'!I10)/2,'Cq and Delta Cq'!D10<'VITA Index summary'!$T$22,2^('Cq and Delta Cq'!I10)/2),"Indeterminate")} -> N/A | E13: =$O$8 -> 1.57 | F13: =IF(OR(AND('Cq and Delta Cq'!F10>'VITA Index summary'!$O$27,'Cq and Delta Cq'!F10<'VITA Index summary'!$O$28),AND('Cq and Delta Cq'!G10>'VITA Index summary'!$O$33,'Cq and Delta Cq'!G10<'VITA Index summary'!$O$34)),"NG detected", "NG not detected") -> NG not detected | G13: {=IFERROR(_xlfn.IFS(F13="NG not detected","N/A",'Cq and Delta Cq'!F10>'VITA Index summary'!$T$28,"Indeterminate",'Cq and Delta Cq'!G10>'VITA Index summary'!$T$34,"Indeterminate",'Cq and Delta Cq'!F10<'VITA Index summary'!$T$28,2^('Cq and Delta Cq'!J10)/2,'Cq and Delta Cq'!G10<'VITA Index summary'!$T$34,2^('Cq and Delta Cq'!J10)/2),"Indeterminate")} -> N/A | H13: =$O$7 -> 1.46 | I13: =IFERROR(IF(AND('VITA Index summary'!$O$39<'Cq and Delta Cq'!E10,'Cq and Delta Cq'!E10<'VITA Index summary'!$O$40),"EC VALID","EC INVALID"),"EC INVALID") -> EC VALID
A14: ='Cq and Delta Cq'!A11 -> A10 | B14: ='Cq and Delta Cq'!B11 -> OM3-009_120 min | C14: =IF(OR(AND('Cq and Delta Cq'!C11>'VITA Index summary'!$O$15,'Cq and Delta Cq'!C11<'VITA Index summary'!$O$16),AND('Cq and Delta Cq'!D11>'VITA Index summary'!$O$21,'Cq and Delta Cq'!D11<'VITA Index summary'!$O$22)),"CT detected", "CT not detected") -> CT not detected | D14: {=IFERROR(_xlfn.IFS(C14="CT not detected","N/A",'Cq and Delta Cq'!C11>'VITA Index summary'!$T$16,"Indeterminate",'Cq and Delta Cq'!D11>'VITA Index summary'!$T$22,"Indeterminate",'Cq and Delta Cq'!C11<'VITA Index summary'!$T$16,2^('Cq and Delta Cq'!I11)/2,'Cq and Delta Cq'!D11<'VITA Index summary'!$T$22,2^('Cq and Delta Cq'!I11)/2),"Indeterminate")} -> N/A | E14: =$O$8 -> 1.57 | F14: =IF(OR(AND('Cq and Delta Cq'!F11>'VITA Index summary'!$O$27,'Cq and Delta Cq'!F11<'VITA Index summary'!$O$28),AND('Cq and Delta Cq'!G11>'VITA Index summary'!$O$33,'Cq and Delta Cq'!G11<'VITA Index summary'!$O$34)),"NG detected", "NG not detected") -> NG detected | G14: {=IFERROR(_xlfn.IFS(F14="NG not detected","N/A",'Cq and Delta Cq'!F11>'VITA Index summary'!$T$28,"Indeterminate",'Cq and Delta Cq'!G11>'VITA Index summary'!$T$34,"Indeterminate",'Cq and Delta Cq'!F11<'VITA Index summary'!$T$28,2^('Cq and Delta Cq'!J11)/2,'Cq and Delta Cq'!G11<'VITA Index summary'!$T$34,2^('Cq and Delta Cq'!J11)/2),"Indeterminate")} -> 1.6620948 | H14: =$O$7 -> 1.46 | I14: =IFERROR(IF(AND('VITA Index summary'!$O$39<'Cq and Delta Cq'!E11,'Cq and Delta Cq'!E11<'VITA Index summary'!$O$40),"EC VALID","EC INVALID"),"EC INVALID") -> EC VALID | N14: CT GAT cut-offs (Detection) | S14: CT GAT cut-offs (Viability)
